<?xml version="1.0"?>

<sdf version="1.9">

    <model name='car'>
        <pose>0 0 1.1 0 -0 0</pose>

        <link name='base_footprint'>
            <pose>0 0 0 0 0 0</pose>
        </link>

        <link name='chassis'>
            <pose>0 0 0 0 0 0</pose>
            <inertial>
                <mass>1.14395</mass>
                <inertia>
                    <ixx>0.126164</ixx>
                    <ixy>0</ixy>
                    <ixz>0</ixz>
                    <iyy>0.416519</iyy>
                    <iyz>0</iyz>
                    <izz>0.481014</izz>
                </inertia>
            </inertial>
            <visual name='visual'>
                <geometry>
                    <box>
                        <size> 4.26 1.7 0.93</size>
                    </box>
                </geometry>
                <material>
                    <ambient>0.5 0.5 1.0 1</ambient>
                    <diffuse>0.5 0.5 1.0 1</diffuse>
                    <specular>0.0 0.0 1.0 1</specular>
                </material>
            </visual>
            <collision name='collision'>
                <geometry>
                    <box>
                        <size>4.26 1.7 0.93</size>
                    </box>
                </geometry>
            </collision>
        </link>

        <link name="front_camera_link">
            <pose>2.16 0 -0.5 0 0 0</pose>
            <inertial>
                <mass>0.1</mass>
                <inertia>
                    <ixx>0.000166667</ixx>
                    <iyy>0.000166667</iyy>
                    <izz>0.000166667</izz>
                </inertia>
            </inertial>
            <collision name="collision">
                <geometry>
                    <box>
                        <size>0.1 0.1 0.1</size>
                    </box>
                </geometry>
            </collision>
            <visual name="visual">
                <geometry>
                    <box>
                        <size>0.1 0.1 0.1</size>
                    </box>
                </geometry>
            </visual>
            <sensor name="camera" type="camera">
                <topic>/front_camera/image</topic>
                <camera>
                    <horizontal_fov>1.396</horizontal_fov>
                    <image>
                        <width>640</width>
                        <height>480</height>
                    </image>
                    <clip>
                        <near>0.1</near>
                        <far>100</far>
                    </clip>
                </camera>
                <always_on>1</always_on>
                <update_rate>30</update_rate>
                <visualize>true</visualize>
            </sensor>

            <sensor name='gpu_lidar' type='gpu_lidar'>"<!-- <pose relative_to='chassis'>0 0 0
                        0 0 0</pose> -->
                    <gz_frame_id>front_camera_link</gz_frame_id>
                    <topic>
                /front_camera</topic>
                    <update_rate>10</update_rate>
                    <ray>
                    <scan>
                        <horizontal>
                            <samples>200</samples>
                            <resolution>1</resolution>
                            <min_angle>-0.7</min_angle>
                            <max_angle>0.7</max_angle>
                        </horizontal>
                        <vertical>
                            <samples>120</samples>
                            <resolution>1</resolution>
                            <min_angle>-0.48</min_angle>
                            <max_angle>0.48</max_angle>
                        </vertical>
                    </scan>
                    <range>
                        <min>0.7</min>
                        <max>32.0</max>
                        <resolution>0.01</resolution>
                    </range>
                </ray>
                    <alwaysOn>
                1</alwaysOn>
                    <visualize>true</visualize>
            </sensor>
        </link>


        <link name="navsat">
            <pose>0 0 0.75 0 0 0</pose>
            <inertial>
                <mass>0.1</mass>
                <inertia>
                    <ixx>0.000166667</ixx>
                    <iyy>0.000166667</iyy>
                    <izz>0.000166667</izz>
                </inertia>
            </inertial>
            <collision name="collision">
                <geometry>
                    <box>
                        <size>0.1 0.1 0.1</size>
                    </box>
                </geometry>
            </collision>
            <visual name="visual">
                <geometry>
                    <box>
                        <size>0.1 0.1 0.1</size>
                    </box>
                </geometry>
            </visual>

            <sensor name="navsat" type="navsat">
                <always_on>1</always_on>
                <update_rate>1</update_rate>
                <topic>navsat</topic>
            </sensor>
            <sensor name="imu_sensor" type="imu">
                <always_on>1</always_on>
                <update_rate>1</update_rate>
                <visualize>true</visualize>
                <topic>imu</topic>
            </sensor>
            <!-- <sensor name='gpu_lidar' type='gpu_lidar'>"
                    <gz_frame_id>navsat</gz_frame_id>
                    <topic>
                    scan</topic>
                    <update_rate>
                        10</update_rate>
                    <ray>
                        <scan>
                            <horizontal>
                                <samples>90</samples>
                                <resolution>1</resolution>
                                <min_angle>-1.57</min_angle>
                                <max_angle>1.57</max_angle>
                            </horizontal>
                            <vertical>
                                <samples>60</samples>
                                <resolution>1</resolution>
                                <min_angle>-1.05</min_angle>
                                <max_angle>1.05</max_angle>
                            </vertical>
                        </scan>
                        <range>
                            <min>0.08</min>
                            <max>10.0</max>
                            <resolution>0.01</resolution>
                        </range>
                    </ray>
                    <alwaysOn>
                    1</alwaysOn>
                    <visualize>true</visualize>
                </sensor> -->
        </link>


        <link name='front_right_wheel'>
            <pose> 1.238 -0.713 -0.75 -1.5707 0 0</pose>
            <inertial>
                <mass>2</mass>
                <inertia>
                    <ixx>0.145833</ixx>
                    <ixy>0</ixy>
                    <ixz>0</ixz>
                    <iyy>0.145833</iyy>
                    <iyz>0</iyz>
                    <izz>0.125</izz>
                </inertia>
            </inertial>
            <visual name='visual'>
                <geometry>
                    <cylinder>
                        <length>0.175</length>
                        <radius>0.285</radius>
                    </cylinder>
                </geometry>
                <material>
                    <ambient>0.2 0.2 0.2 1</ambient>
                    <diffuse>0.2 0.2 0.2 1</diffuse>
                    <specular>0.2 0.2 0.2 1</specular>
                </material>
            </visual>
            <collision name='collision'>
                <geometry>
                    <cylinder>
                        <length>0.175</length>
                        <radius>0.3</radius>
                    </cylinder>
                </geometry>
                <surface>
                    <friction>
                        <ode>
                            <mu>0.5</mu>
                            <mu2>1.0</mu2>
                            <fdir1>0 0 1</fdir1>
                        </ode>
                        <bullet>
                            <friction>0.5</friction>
                            <friction2>1</friction2>
                            <rolling_friction>0.1</rolling_friction>
                        </bullet>
                    </friction>
                </surface>
            </collision>
        </link>

        <link name='front_left_wheel'>
            <pose> 1.238 0.713 -0.75 -1.5707 0 0</pose>
            <inertial>
                <mass>2</mass>
                <inertia>
                    <ixx>0.145833</ixx>
                    <ixy>0</ixy>
                    <ixz>0</ixz>
                    <iyy>0.145833</iyy>
                    <iyz>0</iyz>
                    <izz>0.125</izz>
                </inertia>
            </inertial>
            <visual name='visual'>
                <geometry>
                    <cylinder>
                        <length>0.175</length>
                        <radius>0.285</radius>
                    </cylinder>
                </geometry>
                <material>
                    <ambient>0.2 0.2 0.2 1</ambient>
                    <diffuse>0.2 0.2 0.2 1</diffuse>
                    <specular>0.2 0.2 0.2 1</specular>
                </material>
            </visual>
            <collision name='collision'>
                <geometry>
                    <cylinder>
                        <length>0.175</length>
                        <radius>0.3</radius>
                    </cylinder>
                </geometry>
                <surface>
                    <friction>
                        <ode>
                            <mu>0.5</mu>
                            <mu2>1.0</mu2>
                            <fdir1>0 0 1</fdir1>
                        </ode>
                        <bullet>
                            <friction>0.5</friction>
                            <friction2>1</friction2>
                            <rolling_friction>0.1</rolling_friction>
                        </bullet>
                    </friction>
                </surface>
            </collision>
        </link>

        <link name="front_left_wheel_steering_link">
            <pose>1.238 0.625 -0.75 0 0 0</pose>
            <inertial>
                <mass>0.5</mass>
                <inertia>
                    <ixx>0.0153</ixx>
                    <iyy>0.025</iyy>
                    <izz>0.0153</izz>
                </inertia>
            </inertial>
            <visual name="steering_link_visual">
                <pose>0 0 0 0 0 0</pose>
                <geometry>
                    <cylinder>
                        <length>0.1</length>
                        <radius>0.03</radius>
                    </cylinder>
                </geometry>
                <material>
                    <ambient>1 1 1</ambient>
                    <diffuse>1 1 1</diffuse>
                </material>
            </visual>
        </link>

        <link name="front_right_wheel_steering_link">
            <pose>1.238 -0.625 -0.75 0 0 0</pose>
            <inertial>
                <mass>0.5</mass>
                <inertia>
                    <ixx>0.0153</ixx>
                    <iyy>0.025</iyy>
                    <izz>0.0153</izz>
                </inertia>
            </inertial>
            <visual name="steering_link_visual">
                <pose>0 0 0 0 0 0</pose>
                <geometry>
                    <cylinder>
                        <length>0.1</length>
                        <radius>0.03</radius>
                    </cylinder>
                </geometry>
                <material>
                    <ambient>1 1 1</ambient>
                    <diffuse>1 1 1</diffuse>
                </material>
            </visual>
        </link>

        <link name='back_left_wheel'>
            <pose> -1.238 0.713 -0.75 -1.5707 0 0</pose>
            <inertial>
                <mass>2</mass>
                <inertia>
                    <ixx>0.145833</ixx>
                    <ixy>0</ixy>
                    <ixz>0</ixz>
                    <iyy>0.145833</iyy>
                    <iyz>0</iyz>
                    <izz>0.125</izz>
                </inertia>
            </inertial>
            <visual name='visual'>
                <geometry>
                    <cylinder>
                        <length>0.15</length>
                        <radius>0.285</radius>
                    </cylinder>
                </geometry>
                <material>
                    <ambient>0.2 0.2 0.2 1</ambient>
                    <diffuse>0.2 0.2 0.2 1</diffuse>
                    <specular>0.2 0.2 0.2 1</specular>
                </material>
            </visual>
            <collision name='collision'>
                <geometry>
                    <cylinder>
                        <length>0.175</length>
                        <radius>0.3</radius>
                    </cylinder>
                </geometry>
                <surface>
                    <friction>
                        <ode>
                            <mu>0.5</mu>
                            <mu2>1.0</mu2>
                            <fdir1>0 0 1</fdir1>
                        </ode>
                        <bullet>
                            <friction>0.5</friction>
                            <friction2>1</friction2>
                            <rolling_friction>0.1</rolling_friction>
                        </bullet>
                    </friction>
                </surface>
            </collision>
        </link>

        <link name='back_right_wheel'>
            <pose> -1.238 -0.713 -0.75 -1.5707 0 0</pose>
            <inertial>
                <mass>2</mass>
                <inertia>
                    <ixx>0.145833</ixx>
                    <ixy>0</ixy>
                    <ixz>0</ixz>
                    <iyy>0.145833</iyy>
                    <iyz>0</iyz>
                    <izz>0.125</izz>
                </inertia>
            </inertial>
            <visual name='visual'>
                <geometry>
                    <cylinder>
                        <length>0.15</length>
                        <radius>0.285</radius>
                    </cylinder>
                </geometry>
                <material>
                    <ambient>0.2 0.2 0.2 1</ambient>
                    <diffuse>0.2 0.2 0.2 1</diffuse>
                    <specular>0.2 0.2 0.2 1</specular>
                </material>
            </visual>
            <collision name='collision'>
                <geometry>
                    <cylinder>
                        <length>0.175</length>
                        <radius>0.3</radius>
                    </cylinder>
                </geometry>
                <surface>
                    <friction>
                        <ode>
                            <mu>0.5</mu>
                            <mu2>1.0</mu2>
                            <fdir1>0 0 1</fdir1>
                        </ode>
                        <bullet>
                            <friction>0.5</friction>
                            <friction2>1</friction2>
                            <rolling_friction>0.1</rolling_friction>
                        </bullet>
                    </friction>
                </surface>
            </collision>
        </link>


        <joint name='base_footprint_joint' type='fixed'>
            <parent>base_footprint</parent>
            <child>chassis</child>
        </joint>

        <joint name='front_left_wheel_joint' type='revolute'>
            <parent>front_left_wheel_steering_link</parent>
            <child>front_left_wheel</child>
            <axis>
                <xyz>0 0 1</xyz>
                <limit>
                    <lower>-1.79769e+308</lower>
                    <upper>1.79769e+308</upper>
                </limit>
            </axis>
        </joint>

        <joint name='back_left_wheel_joint' type='revolute'>
            <parent>chassis</parent>
            <child>back_left_wheel</child>
            <axis>
                <xyz>0 0 1</xyz>
                <limit>
                    <lower>-1.79769e+308</lower>
                    <upper>1.79769e+308</upper>
                </limit>
            </axis>
        </joint>

        <joint name='front_right_wheel_joint' type='revolute'>
            <parent>front_right_wheel_steering_link</parent>
            <child>front_right_wheel</child>
            <axis>
                <xyz>0 0 1</xyz>
                <limit>
                    <lower>-1.79769e+308</lower>
                    <upper>1.79769e+308</upper>
                </limit>
            </axis>
        </joint>

        <joint name='back_right_wheel_joint' type='revolute'>
            <parent>chassis</parent>
            <child>back_right_wheel</child>
            <axis>
                <xyz>0 0 1</xyz>
                <limit>
                    <lower>-1.79769e+308</lower>
                    <upper>1.79769e+308</upper>
                </limit>
            </axis>
        </joint>

        <joint name="front_left_wheel_steering_joint" type="revolute">
            <child>front_left_wheel_steering_link</child>
            <parent>chassis</parent>
            <axis>
                <xyz>0 0 1</xyz>
                <limit>
                    <lower>-0.6</lower>
                    <upper>+0.6</upper>
                    <velocity>1.0</velocity>
                    <effort>25</effort>
                </limit>
            </axis>
        </joint>

        <joint name="front_right_wheel_steering_joint" type="revolute">
            <parent>chassis</parent>
            <child>front_right_wheel_steering_link</child>
            <axis>
                <xyz>0 0 1</xyz>
                <limit>
                    <lower>-0.6</lower>
                    <upper>+0.6</upper>
                    <velocity>1.0</velocity>
                    <effort>25</effort>
                </limit>
            </axis>
        </joint>

        <joint name='navsat_joint' type='fixed'>
            <parent>chassis</parent>
            <child>navsat</child>
        </joint>

        <joint name='camera_joint' type='fixed'>
            <parent>chassis</parent>
            <child>front_camera_link</child>
        </joint>


        <plugin filename="ignition-gazebo-ackermann-steering-system"
            name="ignition::gazebo::systems::AckermannSteering">
            <left_joint>front_left_wheel_joint</left_joint>
            <left_joint>back_left_wheel_joint</left_joint>
            <right_joint>front_right_wheel_joint</right_joint>
            <right_joint>back_right_wheel_joint</right_joint>
            <left_steering_joint>front_left_wheel_steering_joint</left_steering_joint>
            <right_steering_joint>front_right_wheel_steering_joint</right_steering_joint>
            <kingpin_width>1.0</kingpin_width>
            <steering_limit>0.715</steering_limit>
            <wheel_base>2.476</wheel_base>
            <wheel_separation>1.426</wheel_separation>
            <wheel_radius>0.285</wheel_radius>
            <odom_publish_rate>50.0</odom_publish_rate>
            <topic>/model/car/cmd_vel</topic>
        </plugin>


        <plugin filename="ignition-gazebo-odometry-publisher-system"
            name="ignition::gazebo::systems::OdometryPublisher">
            <odom_frame>odom</odom_frame>
            <robot_base_frame>chassis</robot_base_frame>
            <odom_publish_frequency>50</odom_publish_frequency>
            <topic>/odometry</topic>
            <dimensions>2</dimensions>
            <child_frame_id>chassis</child_frame_id>
        </plugin>


        <plugin filename="gz-sim-joint-state-publisher-system"
            name="ignition::gazebo::systems::JointStatePublisher">
            <joint_name>back_right_wheel_joint</joint_name>
            <joint_name>back_left_wheel_joint</joint_name>
            <joint_name>front_right_wheel_joint</joint_name>
            <joint_name>front_left_wheel_joint</joint_name>
            <joint_name>front_right_wheel_steering_joint</joint_name>
            <joint_name>front_left_wheel_steering_joint</joint_name>
            <topic>/joint_states</topic>
            <rate>50</rate>
        </plugin>


        <plugin
            filename="gz-sim-pose-publisher-system"
            name="ignition::gazebo::systems::PosePublisher">
            <publish_link_pose>true</publish_link_pose>
            <publish_sensor_pose>true</publish_sensor_pose>
        </plugin>


    </model>

</sdf>